Workbook

Sheet Plastic
A1: Plastic Data from Gold Coast to Sunshine Coast | H1: Date | I1: 26.06.2026
A2: Suburb / Node | B2: Geographic Zone | C2: Governance Authority | D2: Key Risk Category | E2: Compliance Checklist / Metric | F2: Requirements | G2: Data Source / Link
A3: Beerburrum | B3: Sunshine Coast | C3: {=_xlfn.IFS(TRIM(B3)="Sunshine Coast","Sunshine Coast Council",TRIM(B3)="Moreton Bay","City of Moreton Bay",TRIM(B3)="Gold Coast","City of Gold Coast",TRIM(B3)="Ipswich","Ipswich City Council",TRUE,"")} -> Sunshine Coast Council | D3: {=_xlfn.IFS(TRIM(B3)="Sunshine Coast", "Environmental Risk (ERA 12 Plastic Processing)", TRIM(B3)="Moreton Bay", "Industrial Operations Risk", TRIM(B3)="Gold Coast", "Logistics & Supply Chain Risk", TRIM(B3)="Ipswich", "Manufacturing Zoning Risk", TRUE, "")} -> Environmental Risk (ERA 12 Plastic Processing) | E3: {=_xlfn.IFS(TRIM(B3)="Sunshine Coast", "Operation Clean Sweep Audit & Daily Machinery Safety Gate Verification", TRIM(B3)="Moreton Bay", "WHS Incident Log & Heavy Equipment Check", TRIM(B3)="Gold Coast", "Transport Fatigue & Loading Bay Audit", TRIM(B3)="Ipswich", "Council Trade Waste Permit Validation", TRUE, "")} -> Operation Clean Sweep Audit & Daily Machinery Safety Gate Verification | F3: {=_xlfn.IFS(TRIM(B3)="Sunshine Coast", "Zero-loss stormwater filtration & chemical containment zones", TRIM(B3)="Moreton Bay", "Machinery isolation guards & mandatory PPE enforcement", TRIM(B3)="Gold Coast", "Distribution logbook validation & freight rest tracking", TRIM(B3)="Ipswich", "Industrial trade effluent testing & zoning layout verification", TRUE, "")} -> Zero-loss stormwater filtration & chemical containment zones | G3: {=_xlfn.IFS(TRIM(B3)="Sunshine Coast", "DESI Industrial Licenses / MS Loop WHS Folder", TRIM(B3)="Moreton Bay", "WorkSafe QLD / Loop Incident Page", TRIM(B3)="Gold Coast", "QLD Transport Regs / Loop Commute Log", TRIM(B3)="Ipswich", "Ipswich City Council Bylaws / Loop Master Register", TRUE, "")} -> DESI Industrial Licenses / MS Loop WHS Folder
A4: Beerwah | B4: Sunshine Coast | C4: {=_xlfn.IFS(TRIM(B4)="Sunshine Coast","Sunshine Coast Council",TRIM(B4)="Moreton Bay","City of Moreton Bay",TRIM(B4)="Gold Coast","City of Gold Coast",TRIM(B4)="Ipswich","Ipswich City Council",TRUE,"")} -> Sunshine Coast Council | D4: {=_xlfn.IFS(TRIM(B4)="Sunshine Coast", "Environmental Risk (ERA 12 Plastic Processing)", TRIM(B4)="Moreton Bay", "Industrial Operations Risk", TRIM(B4)="Gold Coast", "Logistics & Supply Chain Risk", TRIM(B4)="Ipswich", "Manufacturing Zoning Risk", TRUE, "")} -> Environmental Risk (ERA 12 Plastic Processing) | E4: {=_xlfn.IFS(TRIM(B4)="Sunshine Coast", "Operation Clean Sweep Audit & Daily Machinery Safety Gate Verification", TRIM(B4)="Moreton Bay", "WHS Incident Log & Heavy Equipment Check", TRIM(B4)="Gold Coast", "Transport Fatigue & Loading Bay Audit", TRIM(B4)="Ipswich", "Council Trade Waste Permit Validation", TRUE, "")} -> Operation Clean Sweep Audit & Daily Machinery Safety Gate Verification | F4: {=_xlfn.IFS(TRIM(B4)="Sunshine Coast", "Zero-loss stormwater filtration & chemical containment zones", TRIM(B4)="Moreton Bay", "Machinery isolation guards & mandatory PPE enforcement", TRIM(B4)="Gold Coast", "Distribution logbook validation & freight rest tracking", TRIM(B4)="Ipswich", "Industrial trade effluent testing & zoning layout verification", TRUE, "")} -> Zero-loss stormwater filtration & chemical containment zones | G4: {=_xlfn.IFS(TRIM(B4)="Sunshine Coast", "DESI Industrial Licenses / MS Loop WHS Folder", TRIM(B4)="Moreton Bay", "WorkSafe QLD / Loop Incident Page", TRIM(B4)="Gold Coast", "QLD Transport Regs / Loop Commute Log", TRIM(B4)="Ipswich", "Ipswich City Council Bylaws / Loop Master Register", TRUE, "")} -> DESI Industrial Licenses / MS Loop WHS Folder
A5: Burpengary | B5: Moreton Bay | C5: {=_xlfn.IFS(TRIM(B5)="Sunshine Coast","Sunshine Coast Council",TRIM(B5)="Moreton Bay","City of Moreton Bay",TRIM(B5)="Gold Coast","City of Gold Coast",TRIM(B5)="Ipswich","Ipswich City Council",TRUE,"")} -> City of Moreton Bay | D5: {=_xlfn.IFS(TRIM(B5)="Sunshine Coast", "Environmental Risk (ERA 12 Plastic Processing)", TRIM(B5)="Moreton Bay", "Industrial Operations Risk", TRIM(B5)="Gold Coast", "Logistics & Supply Chain Risk", TRIM(B5)="Ipswich", "Manufacturing Zoning Risk", TRUE, "")} -> Industrial Operations Risk | E5: {=_xlfn.IFS(TRIM(B5)="Sunshine Coast", "Operation Clean Sweep Audit & Daily Machinery Safety Gate Verification", TRIM(B5)="Moreton Bay", "WHS Incident Log & Heavy Equipment Check", TRIM(B5)="Gold Coast", "Transport Fatigue & Loading Bay Audit", TRIM(B5)="Ipswich", "Council Trade Waste Permit Validation", TRUE, "")} -> WHS Incident Log & Heavy Equipment Check | F5: {=_xlfn.IFS(TRIM(B5)="Sunshine Coast", "Zero-loss stormwater filtration & chemical containment zones", TRIM(B5)="Moreton Bay", "Machinery isolation guards & mandatory PPE enforcement", TRIM(B5)="Gold Coast", "Distribution logbook validation & freight rest tracking", TRIM(B5)="Ipswich", "Industrial trade effluent testing & zoning layout verification", TRUE, "")} -> Machinery isolation guards & mandatory PPE enforcement | G5: {=_xlfn.IFS(TRIM(B5)="Sunshine Coast", "DESI Industrial Licenses / MS Loop WHS Folder", TRIM(B5)="Moreton Bay", "WorkSafe QLD / Loop Incident Page", TRIM(B5)="Gold Coast", "QLD Transport Regs / Loop Commute Log", TRIM(B5)="Ipswich", "Ipswich City Council Bylaws / Loop Master Register", TRUE, "")} -> WorkSafe QLD / Loop Incident Page
A6: Caboolture | B6: Moreton Bay | C6: {=_xlfn.IFS(TRIM(B6)="Sunshine Coast","Sunshine Coast Council",TRIM(B6)="Moreton Bay","City of Moreton Bay",TRIM(B6)="Gold Coast","City of Gold Coast",TRIM(B6)="Ipswich","Ipswich City Council",TRUE,"")} -> City of Moreton Bay | D6: {=_xlfn.IFS(TRIM(B6)="Sunshine Coast", "Environmental Risk (ERA 12 Plastic Processing)", TRIM(B6)="Moreton Bay", "Industrial Operations Risk", TRIM(B6)="Gold Coast", "Logistics & Supply Chain Risk", TRIM(B6)="Ipswich", "Manufacturing Zoning Risk", TRUE, "")} -> Industrial Operations Risk | E6: {=_xlfn.IFS(TRIM(B6)="Sunshine Coast", "Operation Clean Sweep Audit & Daily Machinery Safety Gate Verification", TRIM(B6)="Moreton Bay", "WHS Incident Log & Heavy Equipment Check", TRIM(B6)="Gold Coast", "Transport Fatigue & Loading Bay Audit", TRIM(B6)="Ipswich", "Council Trade Waste Permit Validation", TRUE, "")} -> WHS Incident Log & Heavy Equipment Check | F6: {=_xlfn.IFS(TRIM(B6)="Sunshine Coast", "Zero-loss stormwater filtration & chemical containment zones", TRIM(B6)="Moreton Bay", "Machinery isolation guards & mandatory PPE enforcement", TRIM(B6)="Gold Coast", "Distribution logbook validation & freight rest tracking", TRIM(B6)="Ipswich", "Industrial trade effluent testing & zoning layout verification", TRUE, "")} -> Machinery isolation guards & mandatory PPE enforcement | G6: {=_xlfn.IFS(TRIM(B6)="Sunshine Coast", "DESI Industrial Licenses / MS Loop WHS Folder", TRIM(B6)="Moreton Bay", "WorkSafe QLD / Loop Incident Page", TRIM(B6)="Gold Coast", "QLD Transport Regs / Loop Commute Log", TRIM(B6)="Ipswich", "Ipswich City Council Bylaws / Loop Master Register", TRUE, "")} -> WorkSafe QLD / Loop Incident Page
A7: Coomera | B7: Gold Coast | C7: {=_xlfn.IFS(TRIM(B7)="Sunshine Coast","Sunshine Coast Council",TRIM(B7)="Moreton Bay","City of Moreton Bay",TRIM(B7)="Gold Coast","City of Gold Coast",TRIM(B7)="Ipswich","Ipswich City Council",TRUE,"")} -> City of Gold Coast | D7: {=_xlfn.IFS(TRIM(B7)="Sunshine Coast", "Environmental Risk (ERA 12 Plastic Processing)", TRIM(B7)="Moreton Bay", "Industrial Operations Risk", TRIM(B7)="Gold Coast", "Logistics & Supply Chain Risk", TRIM(B7)="Ipswich", "Manufacturing Zoning Risk", TRUE, "")} -> Logistics & Supply Chain Risk | E7: {=_xlfn.IFS(TRIM(B7)="Sunshine Coast", "Operation Clean Sweep Audit & Daily Machinery Safety Gate Verification", TRIM(B7)="Moreton Bay", "WHS Incident Log & Heavy Equipment Check", TRIM(B7)="Gold Coast", "Transport Fatigue & Loading Bay Audit", TRIM(B7)="Ipswich", "Council Trade Waste Permit Validation", TRUE, "")} -> Transport Fatigue & Loading Bay Audit | F7: {=_xlfn.IFS(TRIM(B7)="Sunshine Coast", "Zero-loss stormwater filtration & chemical containment zones", TRIM(B7)="Moreton Bay", "Machinery isolation guards & mandatory PPE enforcement", TRIM(B7)="Gold Coast", "Distribution logbook validation & freight rest tracking", TRIM(B7)="Ipswich", "Industrial trade effluent testing & zoning layout verification", TRUE, "")} -> Distribution logbook validation & freight rest tracking | G7: {=_xlfn.IFS(TRIM(B7)="Sunshine Coast", "DESI Industrial Licenses / MS Loop WHS Folder", TRIM(B7)="Moreton Bay", "WorkSafe QLD / Loop Incident Page", TRIM(B7)="Gold Coast", "QLD Transport Regs / Loop Commute Log", TRIM(B7)="Ipswich", "Ipswich City Council Bylaws / Loop Master Register", TRUE, "")} -> QLD Transport Regs / Loop Commute Log
A8: Dakabin | B8: Moreton Bay | C8: {=_xlfn.IFS(TRIM(B8)="Sunshine Coast","Sunshine Coast Council",TRIM(B8)="Moreton Bay","City of Moreton Bay",TRIM(B8)="Gold Coast","City of Gold Coast",TRIM(B8)="Ipswich","Ipswich City Council",TRUE,"")} -> City of Moreton Bay | D8: {=_xlfn.IFS(TRIM(B8)="Sunshine Coast", "Environmental Risk (ERA 12 Plastic Processing)", TRIM(B8)="Moreton Bay", "Industrial Operations Risk", TRIM(B8)="Gold Coast", "Logistics & Supply Chain Risk", TRIM(B8)="Ipswich", "Manufacturing Zoning Risk", TRUE, "")} -> Industrial Operations Risk | E8: {=_xlfn.IFS(TRIM(B8)="Sunshine Coast", "Operation Clean Sweep Audit & Daily Machinery Safety Gate Verification", TRIM(B8)="Moreton Bay", "WHS Incident Log & Heavy Equipment Check", TRIM(B8)="Gold Coast", "Transport Fatigue & Loading Bay Audit", TRIM(B8)="Ipswich", "Council Trade Waste Permit Validation", TRUE, "")} -> WHS Incident Log & Heavy Equipment Check | F8: {=_xlfn.IFS(TRIM(B8)="Sunshine Coast", "Zero-loss stormwater filtration & chemical containment zones", TRIM(B8)="Moreton Bay", "Machinery isolation guards & mandatory PPE enforcement", TRIM(B8)="Gold Coast", "Distribution logbook validation & freight rest tracking", TRIM(B8)="Ipswich", "Industrial trade effluent testing & zoning layout verification", TRUE, "")} -> Machinery isolation guards & mandatory PPE enforcement | G8: {=_xlfn.IFS(TRIM(B8)="Sunshine Coast", "DESI Industrial Licenses / MS Loop WHS Folder", TRIM(B8)="Moreton Bay", "WorkSafe QLD / Loop Incident Page", TRIM(B8)="Gold Coast", "QLD Transport Regs / Loop Commute Log", TRIM(B8)="Ipswich", "Ipswich City Council Bylaws / Loop Master Register", TRUE, "")} -> WorkSafe QLD / Loop Incident Page
A9: Elimbah | B9: Sunshine Coast | C9: {=_xlfn.IFS(TRIM(B9)="Sunshine Coast","Sunshine Coast Council",TRIM(B9)="Moreton Bay","City of Moreton Bay",TRIM(B9)="Gold Coast","City of Gold Coast",TRIM(B9)="Ipswich","Ipswich City Council",TRUE,"")} -> Sunshine Coast Council | D9: {=_xlfn.IFS(TRIM(B9)="Sunshine Coast", "Environmental Risk (ERA 12 Plastic Processing)", TRIM(B9)="Moreton Bay", "Industrial Operations Risk", TRIM(B9)="Gold Coast", "Logistics & Supply Chain Risk", TRIM(B9)="Ipswich", "Manufacturing Zoning Risk", TRUE, "")} -> Environmental Risk (ERA 12 Plastic Processing) | E9: {=_xlfn.IFS(TRIM(B9)="Sunshine Coast", "Operation Clean Sweep Audit & Daily Machinery Safety Gate Verification", TRIM(B9)="Moreton Bay", "WHS Incident Log & Heavy Equipment Check", TRIM(B9)="Gold Coast", "Transport Fatigue & Loading Bay Audit", TRIM(B9)="Ipswich", "Council Trade Waste Permit Validation", TRUE, "")} -> Operation Clean Sweep Audit & Daily Machinery Safety Gate Verification | F9: {=_xlfn.IFS(TRIM(B9)="Sunshine Coast", "Zero-loss stormwater filtration & chemical containment zones", TRIM(B9)="Moreton Bay", "Machinery isolation guards & mandatory PPE enforcement", TRIM(B9)="Gold Coast", "Distribution logbook validation & freight rest tracking", TRIM(B9)="Ipswich", "Industrial trade effluent testing & zoning layout verification", TRUE, "")} -> Zero-loss stormwater filtration & chemical containment zones | G9: {=_xlfn.IFS(TRIM(B9)="Sunshine Coast", "DESI Industrial Licenses / MS Loop WHS Folder", TRIM(B9)="Moreton Bay", "WorkSafe QLD / Loop Incident Page", TRIM(B9)="Gold Coast", "QLD Transport Regs / Loop Commute Log", TRIM(B9)="Ipswich", "Ipswich City Council Bylaws / Loop Master Register", TRUE, "")} -> DESI Industrial Licenses / MS Loop WHS Folder
A10: Eudlo | B10: Sunshine Coast | C10: {=_xlfn.IFS(TRIM(B10)="Sunshine Coast","Sunshine Coast Council",TRIM(B10)="Moreton Bay","City of Moreton Bay",TRIM(B10)="Gold Coast","City of Gold Coast",TRIM(B10)="Ipswich","Ipswich City Council",TRUE,"")} -> Sunshine Coast Council | D10: {=_xlfn.IFS(TRIM(B10)="Sunshine Coast", "Environmental Risk (ERA 12 Plastic Processing)", TRIM(B10)="Moreton Bay", "Industrial Operations Risk", TRIM(B10)="Gold Coast", "Logistics & Supply Chain Risk", TRIM(B10)="Ipswich", "Manufacturing Zoning Risk", TRUE, "")} -> Environmental Risk (ERA 12 Plastic Processing) | E10: {=_xlfn.IFS(TRIM(B10)="Sunshine Coast", "Operation Clean Sweep Audit & Daily Machinery Safety Gate Verification", TRIM(B10)="Moreton Bay", "WHS Incident Log & Heavy Equipment Check", TRIM(B10)="Gold Coast", "Transport Fatigue & Loading Bay Audit", TRIM(B10)="Ipswich", "Council Trade Waste Permit Validation", TRUE, "")} -> Operation Clean Sweep Audit & Daily Machinery Safety Gate Verification | F10: {=_xlfn.IFS(TRIM(B10)="Sunshine Coast", "Zero-loss stormwater filtration & chemical containment zones", TRIM(B10)="Moreton Bay", "Machinery isolation guards & mandatory PPE enforcement", TRIM(B10)="Gold Coast", "Distribution logbook validation & freight rest tracking", TRIM(B10)="Ipswich", "Industrial trade effluent testing & zoning layout verification", TRUE, "")} -> Zero-loss stormwater filtration & chemical containment zones | G10: {=_xlfn.IFS(TRIM(B10)="Sunshine Coast", "DESI Industrial Licenses / MS Loop WHS Folder", TRIM(B10)="Moreton Bay", "WorkSafe QLD / Loop Incident Page", TRIM(B10)="Gold Coast", "QLD Transport Regs / Loop Commute Log", TRIM(B10)="Ipswich", "Ipswich City Council Bylaws / Loop Master Register", TRUE, "")} -> DESI Industrial Licenses / MS Loop WHS Folder
A11: Glass House Mountains | B11: Sunshine Coast | C11: {=_xlfn.IFS(TRIM(B11)="Sunshine Coast","Sunshine Coast Council",TRIM(B11)="Moreton Bay","City of Moreton Bay",TRIM(B11)="Gold Coast","City of Gold Coast",TRIM(B11)="Ipswich","Ipswich City Council",TRUE,"")} -> Sunshine Coast Council | D11: {=_xlfn.IFS(TRIM(B11)="Sunshine Coast", "Environmental Risk (ERA 12 Plastic Processing)", TRIM(B11)="Moreton Bay", "Industrial Operations Risk", TRIM(B11)="Gold Coast", "Logistics & Supply Chain Risk", TRIM(B11)="Ipswich", "Manufacturing Zoning Risk", TRUE, "")} -> Environmental Risk (ERA 12 Plastic Processing) | E11: {=_xlfn.IFS(TRIM(B11)="Sunshine Coast", "Operation Clean Sweep Audit & Daily Machinery Safety Gate Verification", TRIM(B11)="Moreton Bay", "WHS Incident Log & Heavy Equipment Check", TRIM(B11)="Gold Coast", "Transport Fatigue & Loading Bay Audit", TRIM(B11)="Ipswich", "Council Trade Waste Permit Validation", TRUE, "")} -> Operation Clean Sweep Audit & Daily Machinery Safety Gate Verification | F11: {=_xlfn.IFS(TRIM(B11)="Sunshine Coast", "Zero-loss stormwater filtration & chemical containment zones", TRIM(B11)="Moreton Bay", "Machinery isolation guards & mandatory PPE enforcement", TRIM(B11)="Gold Coast", "Distribution logbook validation & freight rest tracking", TRIM(B11)="Ipswich", "Industrial trade effluent testing & zoning layout verification", TRUE, "")} -> Zero-loss stormwater filtration & chemical containment zones | G11: {=_xlfn.IFS(TRIM(B11)="Sunshine Coast", "DESI Industrial Licenses / MS Loop WHS Folder", TRIM(B11)="Moreton Bay", "WorkSafe QLD / Loop Incident Page", TRIM(B11)="Gold Coast", "QLD Transport Regs / Loop Commute Log", TRIM(B11)="Ipswich", "Ipswich City Council Bylaws / Loop Master Register", TRUE, "")} -> DESI Industrial Licenses / MS Loop WHS Folder
A12: Helensvale | B12: Gold Coast | C12: {=_xlfn.IFS(TRIM(B12)="Sunshine Coast","Sunshine Coast Council",TRIM(B12)="Moreton Bay","City of Moreton Bay",TRIM(B12)="Gold Coast","City of Gold Coast",TRIM(B12)="Ipswich","Ipswich City Council",TRUE,"")} -> City of Gold Coast | D12: {=_xlfn.IFS(TRIM(B12)="Sunshine Coast", "Environmental Risk (ERA 12 Plastic Processing)", TRIM(B12)="Moreton Bay", "Industrial Operations Risk", TRIM(B12)="Gold Coast", "Logistics & Supply Chain Risk", TRIM(B12)="Ipswich", "Manufacturing Zoning Risk", TRUE, "")} -> Logistics & Supply Chain Risk | E12: {=_xlfn.IFS(TRIM(B12)="Sunshine Coast", "Operation Clean Sweep Audit & Daily Machinery Safety Gate Verification", TRIM(B12)="Moreton Bay", "WHS Incident Log & Heavy Equipment Check", TRIM(B12)="Gold Coast", "Transport Fatigue & Loading Bay Audit", TRIM(B12)="Ipswich", "Council Trade Waste Permit Validation", TRUE, "")} -> Transport Fatigue & Loading Bay Audit | F12: {=_xlfn.IFS(TRIM(B12)="Sunshine Coast", "Zero-loss stormwater filtration & chemical containment zones", TRIM(B12)="Moreton Bay", "Machinery isolation guards & mandatory PPE enforcement", TRIM(B12)="Gold Coast", "Distribution logbook validation & freight rest tracking", TRIM(B12)="Ipswich", "Industrial trade effluent testing & zoning layout verification", TRUE, "")} -> Distribution logbook validation & freight rest tracking | G12: {=_xlfn.IFS(TRIM(B12)="Sunshine Coast", "DESI Industrial Licenses / MS Loop WHS Folder", TRIM(B12)="Moreton Bay", "WorkSafe QLD / Loop Incident Page", TRIM(B12)="Gold Coast", "QLD Transport Regs / Loop Commute Log", TRIM(B12)="Ipswich", "Ipswich City Council Bylaws / Loop Master Register", TRUE, "")} -> QLD Transport Regs / Loop Commute Log
A13: Hope Island | B13: Gold Coast | C13: {=_xlfn.IFS(TRIM(B13)="Sunshine Coast","Sunshine Coast Council",TRIM(B13)="Moreton Bay","City of Moreton Bay",TRIM(B13)="Gold Coast","City of Gold Coast",TRIM(B13)="Ipswich","Ipswich City Council",TRUE,"")} -> City of Gold Coast | D13: {=_xlfn.IFS(TRIM(B13)="Sunshine Coast", "Environmental Risk (ERA 12 Plastic Processing)", TRIM(B13)="Moreton Bay", "Industrial Operations Risk", TRIM(B13)="Gold Coast", "Logistics & Supply Chain Risk", TRIM(B13)="Ipswich", "Manufacturing Zoning Risk", TRUE, "")} -> Logistics & Supply Chain Risk | E13: {=_xlfn.IFS(TRIM(B13)="Sunshine Coast", "Operation Clean Sweep Audit & Daily Machinery Safety Gate Verification", TRIM(B13)="Moreton Bay", "WHS Incident Log & Heavy Equipment Check", TRIM(B13)="Gold Coast", "Transport Fatigue & Loading Bay Audit", TRIM(B13)="Ipswich", "Council Trade Waste Permit Validation", TRUE, "")} -> Transport Fatigue & Loading Bay Audit | F13: {=_xlfn.IFS(TRIM(B13)="Sunshine Coast", "Zero-loss stormwater filtration & chemical containment zones", TRIM(B13)="Moreton Bay", "Machinery isolation guards & mandatory PPE enforcement", TRIM(B13)="Gold Coast", "Distribution logbook validation & freight rest tracking", TRIM(B13)="Ipswich", "Industrial trade effluent testing & zoning layout verification", TRUE, "")} -> Distribution logbook validation & freight rest tracking | G13: {=_xlfn.IFS(TRIM(B13)="Sunshine Coast", "DESI Industrial Licenses / MS Loop WHS Folder", TRIM(B13)="Moreton Bay", "WorkSafe QLD / Loop Incident Page", TRIM(B13)="Gold Coast", "QLD Transport Regs / Loop Commute Log", TRIM(B13)="Ipswich", "Ipswich City Council Bylaws / Loop Master Register", TRUE, "")} -> QLD Transport Regs / Loop Commute Log
A14: Ipswich CBD | B14: Ipswich | C14: {=_xlfn.IFS(TRIM(B14)="Sunshine Coast","Sunshine Coast Council",TRIM(B14)="Moreton Bay","City of Moreton Bay",TRIM(B14)="Gold Coast","City of Gold Coast",TRIM(B14)="Ipswich","Ipswich City Council",TRUE,"")} -> Ipswich City Council | D14: {=_xlfn.IFS(TRIM(B14)="Sunshine Coast", "Environmental Risk (ERA 12 Plastic Processing)", TRIM(B14)="Moreton Bay", "Industrial Operations Risk", TRIM(B14)="Gold Coast", "Logistics & Supply Chain Risk", TRIM(B14)="Ipswich", "Manufacturing Zoning Risk", TRUE, "")} -> Manufacturing Zoning Risk | E14: {=_xlfn.IFS(TRIM(B14)="Sunshine Coast", "Operation Clean Sweep Audit & Daily Machinery Safety Gate Verification", TRIM(B14)="Moreton Bay", "WHS Incident Log & Heavy Equipment Check", TRIM(B14)="Gold Coast", "Transport Fatigue & Loading Bay Audit", TRIM(B14)="Ipswich", "Council Trade Waste Permit Validation", TRUE, "")} -> Council Trade Waste Permit Validation | F14: {=_xlfn.IFS(TRIM(B14)="Sunshine Coast", "Zero-loss stormwater filtration & chemical containment zones", TRIM(B14)="Moreton Bay", "Machinery isolation guards & mandatory PPE enforcement", TRIM(B14)="Gold Coast", "Distribution logbook validation & freight rest tracking", TRIM(B14)="Ipswich", "Industrial trade effluent testing & zoning layout verification", TRUE, "")} -> Industrial trade effluent testing & zoning layout verification | G14: {=_xlfn.IFS(TRIM(B14)="Sunshine Coast", "DESI Industrial Licenses / MS Loop WHS Folder", TRIM(B14)="Moreton Bay", "WorkSafe QLD / Loop Incident Page", TRIM(B14)="Gold Coast", "QLD Transport Regs / Loop Commute Log", TRIM(B14)="Ipswich", "Ipswich City Council Bylaws / Loop Master Register", TRUE, "")} -> Ipswich City Council Bylaws / Loop Master Register
... A38: Woombye | B38: Sunshine Coast | C38: {=_xlfn.IFS(TRIM(B38)="Sunshine Coast","Sunshine Coast Council",TRIM(B38)="Moreton Bay","City of Moreton Bay",TRIM(B38)="Gold Coast","City of Gold Coast",TRIM(B38)="Ipswich","Ipswich City Council",TRUE,"")} -> Sunshine Coast Council | D38: {=_xlfn.IFS(TRIM(B38)="Sunshine Coast", "Environmental Risk (ERA 12 Plastic Processing)", TRIM(B38)="Moreton Bay", "Industrial Operations Risk", TRIM(B38)="Gold Coast", "Logistics & Supply Chain Risk", TRIM(B38)="Ipswich", "Manufacturing Zoning Risk", TRUE, "")} -> Environmental Risk (ERA 12 Plastic Processing) | E38: {=_xlfn.IFS(TRIM(B38)="Sunshine Coast", "Operation Clean Sweep Audit & Daily Machinery Safety Gate Verification", TRIM(B38)="Moreton Bay", "WHS Incident Log & Heavy Equipment Check", TRIM(B38)="Gold Coast", "Transport Fatigue & Loading Bay Audit", TRIM(B38)="Ipswich", "Council Trade Waste Permit Validation", TRUE, "")} -> Operation Clean Sweep Audit & Daily Machinery Safety Gate Verification | F38: {=_xlfn.IFS(TRIM(B38)="Sunshine Coast", "Zero-loss stormwater filtration & chemical containment zones", TRIM(B38)="Moreton Bay", "Machinery isolation guards & mandatory PPE enforcement", TRIM(B38)="Gold Coast", "Distribution logbook validation & freight rest tracking", TRIM(B38)="Ipswich", "Industrial trade effluent testing & zoning layout verification", TRUE, "")} -> Zero-loss stormwater filtration & chemical containment zones | G38: {=_xlfn.IFS(TRIM(B38)="Sunshine Coast", "DESI Industrial Licenses / MS Loop WHS Folder", TRIM(B38)="Moreton Bay", "WorkSafe QLD / Loop Incident Page", TRIM(B38)="Gold Coast", "QLD Transport Regs / Loop Commute Log", TRIM(B38)="Ipswich", "Ipswich City Council Bylaws / Loop Master Register", TRUE, "")} -> DESI Industrial Licenses / MS Loop WHS Folder

Sheet Food
A1: Food Data from Gold Coast to Sunshine Coast | H1: Date | I1: 26.06.2026
A2: Suburb / Node | B2: Geographic Zone | C2: Governance Authority | D2: Key Risk Category | E2: Compliance Checklist / Metric | F2: Requirements | G2: Data Source / Link
A3: Beerburrum | B3: Sunshine Coast | C3: {=_xlfn.IFS(TRIM(B3)="Sunshine Coast","Sunshine Coast Council",TRIM(B3)="Moreton Bay","City of Moreton Bay",TRIM(B3)="Gold Coast","City of Gold Coast",TRIM(B3)="Ipswich","Ipswich City Council",TRUE,"")} -> Sunshine Coast Council | D3: {=_xlfn.IFS(TRIM(B3)="Sunshine Coast","Biosecurity & Trade Waste Liquid Risk",TRIM(B3)="Moreton Bay","Commercial Effluent & Sewer Network Blockage Risk",TRIM(B3)="Gold Coast","FOG (Fats, Oils & Grease) Overload Risk",TRIM(B3)="Ipswich","Liquid Trade Waste Compliance & Pathogen Risk",TRUE,"")} -> Biosecurity & Trade Waste Liquid Risk | E3: {=_xlfn.IFS(TRIM(B3)="Sunshine Coast","Grease Trap Maintenance Log & Food Safety Supervisor Certificate Validation",TRIM(B3)="Moreton Bay","Unitywater Digital QR Code Tag Scan & Settleable Solids Log",TRIM(B3)="Gold Coast","Licensed Liquid Waste Contractor Extraction & Baffle Structural Check",TRIM(B3)="Ipswich","Urban Utilities Approved Sizing Metric & 25% FOG Accumulation Audit",TRUE,"")} -> Grease Trap Maintenance Log & Food Safety Supervisor Certificate Validation | F3: {=_xlfn.IFS(TRIM(B3)="Sunshine Coast","A mandatory grease arrestor pump-out every 13 weeks minimum",TRIM(B3)="Moreton Bay","Mandatory compliance with Unitywater Trade Waste Policy & scheduled pump-outs",TRIM(B3)="Gold Coast","All wastewater from food prep, floor wastes, and dishwashers must pass through approved trap",TRIM(B3)="Ipswich","Routine cleaning intervals mandated by Urban Utilities (ranging from 4 to 12 weeks)",TRUE,"")} -> A mandatory grease arrestor pump-out every 13 weeks minimum | G3: {=_xlfn.IFS(TRIM(B3)="Sunshine Coast", "Unitywater Trade Waste Permit / MS Loop Food Folder", TRIM(B3)="Moreton Bay", "Water Supply (Safety and Reliability) Act 2008 / Unitywater Policy", TRIM(B3)="Gold Coast", "City of Gold Coast Liquid Trade Waste Guidelines", TRIM(B3)="Ipswich", "Urban Utilities Trade Waste Program / Ipswich Environmental Health Regs", TRUE, "")} -> Unitywater Trade Waste Permit / MS Loop Food Folder
A4: Beerwah | B4: Sunshine Coast | C4: {=_xlfn.IFS(TRIM(B4)="Sunshine Coast","Sunshine Coast Council",TRIM(B4)="Moreton Bay","City of Moreton Bay",TRIM(B4)="Gold Coast","City of Gold Coast",TRIM(B4)="Ipswich","Ipswich City Council",TRUE,"")} -> Sunshine Coast Council | D4: {=_xlfn.IFS(TRIM(B4)="Sunshine Coast","Biosecurity & Trade Waste Liquid Risk",TRIM(B4)="Moreton Bay","Commercial Effluent & Sewer Network Blockage Risk",TRIM(B4)="Gold Coast","FOG (Fats, Oils & Grease) Overload Risk",TRIM(B4)="Ipswich","Liquid Trade Waste Compliance & Pathogen Risk",TRUE,"")} -> Biosecurity & Trade Waste Liquid Risk | E4: {=_xlfn.IFS(TRIM(B4)="Sunshine Coast","Grease Trap Maintenance Log & Food Safety Supervisor Certificate Validation",TRIM(B4)="Moreton Bay","Unitywater Digital QR Code Tag Scan & Settleable Solids Log",TRIM(B4)="Gold Coast","Licensed Liquid Waste Contractor Extraction & Baffle Structural Check",TRIM(B4)="Ipswich","Urban Utilities Approved Sizing Metric & 25% FOG Accumulation Audit",TRUE,"")} -> Grease Trap Maintenance Log & Food Safety Supervisor Certificate Validation | F4: {=_xlfn.IFS(TRIM(B4)="Sunshine Coast","A mandatory grease arrestor pump-out every 13 weeks minimum",TRIM(B4)="Moreton Bay","Mandatory compliance with Unitywater Trade Waste Policy & scheduled pump-outs",TRIM(B4)="Gold Coast","All wastewater from food prep, floor wastes, and dishwashers must pass through approved trap",TRIM(B4)="Ipswich","Routine cleaning intervals mandated by Urban Utilities (ranging from 4 to 12 weeks)",TRUE,"")} -> A mandatory grease arrestor pump-out every 13 weeks minimum | G4: {=_xlfn.IFS(TRIM(B4)="Sunshine Coast", "Unitywater Trade Waste Permit / MS Loop Food Folder", TRIM(B4)="Moreton Bay", "Water Supply (Safety and Reliability) Act 2008 / Unitywater Policy", TRIM(B4)="Gold Coast", "City of Gold Coast Liquid Trade Waste Guidelines", TRIM(B4)="Ipswich", "Urban Utilities Trade Waste Program / Ipswich Environmental Health Regs", TRUE, "")} -> Unitywater Trade Waste Permit / MS Loop Food Folder
A5: Burpengary | B5: Moreton Bay | C5: {=_xlfn.IFS(TRIM(B5)="Sunshine Coast","Sunshine Coast Council",TRIM(B5)="Moreton Bay","City of Moreton Bay",TRIM(B5)="Gold Coast","City of Gold Coast",TRIM(B5)="Ipswich","Ipswich City Council",TRUE,"")} -> City of Moreton Bay | D5: {=_xlfn.IFS(TRIM(B5)="Sunshine Coast","Biosecurity & Trade Waste Liquid Risk",TRIM(B5)="Moreton Bay","Commercial Effluent & Sewer Network Blockage Risk",TRIM(B5)="Gold Coast","FOG (Fats, Oils & Grease) Overload Risk",TRIM(B5)="Ipswich","Liquid Trade Waste Compliance & Pathogen Risk",TRUE,"")} -> Commercial Effluent & Sewer Network Blockage Risk | E5: {=_xlfn.IFS(TRIM(B5)="Sunshine Coast","Grease Trap Maintenance Log & Food Safety Supervisor Certificate Validation",TRIM(B5)="Moreton Bay","Unitywater Digital QR Code Tag Scan & Settleable Solids Log",TRIM(B5)="Gold Coast","Licensed Liquid Waste Contractor Extraction & Baffle Structural Check",TRIM(B5)="Ipswich","Urban Utilities Approved Sizing Metric & 25% FOG Accumulation Audit",TRUE,"")} -> Unitywater Digital QR Code Tag Scan & Settleable Solids Log | F5: {=_xlfn.IFS(TRIM(B5)="Sunshine Coast","A mandatory grease arrestor pump-out every 13 weeks minimum",TRIM(B5)="Moreton Bay","Mandatory compliance with Unitywater Trade Waste Policy & scheduled pump-outs",TRIM(B5)="Gold Coast","All wastewater from food prep, floor wastes, and dishwashers must pass through approved trap",TRIM(B5)="Ipswich","Routine cleaning intervals mandated by Urban Utilities (ranging from 4 to 12 weeks)",TRUE,"")} -> Mandatory compliance with Unitywater Trade Waste Policy & scheduled pump-outs | G5: {=_xlfn.IFS(TRIM(B5)="Sunshine Coast", "Unitywater Trade Waste Permit / MS Loop Food Folder", TRIM(B5)="Moreton Bay", "Water Supply (Safety and Reliability) Act 2008 / Unitywater Policy", TRIM(B5)="Gold Coast", "City of Gold Coast Liquid Trade Waste Guidelines", TRIM(B5)="Ipswich", "Urban Utilities Trade Waste Program / Ipswich Environmental Health Regs", TRUE, "")} -> Water Supply (Safety and Reliability) Act 2008 / Unitywater Policy
A6: Caboolture | B6: Moreton Bay | C6: {=_xlfn.IFS(TRIM(B6)="Sunshine Coast","Sunshine Coast Council",TRIM(B6)="Moreton Bay","City of Moreton Bay",TRIM(B6)="Gold Coast","City of Gold Coast",TRIM(B6)="Ipswich","Ipswich City Council",TRUE,"")} -> City of Moreton Bay | D6: {=_xlfn.IFS(TRIM(B6)="Sunshine Coast","Biosecurity & Trade Waste Liquid Risk",TRIM(B6)="Moreton Bay","Commercial Effluent & Sewer Network Blockage Risk",TRIM(B6)="Gold Coast","FOG (Fats, Oils & Grease) Overload Risk",TRIM(B6)="Ipswich","Liquid Trade Waste Compliance & Pathogen Risk",TRUE,"")} -> Commercial Effluent & Sewer Network Blockage Risk | E6: {=_xlfn.IFS(TRIM(B6)="Sunshine Coast","Grease Trap Maintenance Log & Food Safety Supervisor Certificate Validation",TRIM(B6)="Moreton Bay","Unitywater Digital QR Code Tag Scan & Settleable Solids Log",TRIM(B6)="Gold Coast","Licensed Liquid Waste Contractor Extraction & Baffle Structural Check",TRIM(B6)="Ipswich","Urban Utilities Approved Sizing Metric & 25% FOG Accumulation Audit",TRUE,"")} -> Unitywater Digital QR Code Tag Scan & Settleable Solids Log | F6: {=_xlfn.IFS(TRIM(B6)="Sunshine Coast","A mandatory grease arrestor pump-out every 13 weeks minimum",TRIM(B6)="Moreton Bay","Mandatory compliance with Unitywater Trade Waste Policy & scheduled pump-outs",TRIM(B6)="Gold Coast","All wastewater from food prep, floor wastes, and dishwashers must pass through approved trap",TRIM(B6)="Ipswich","Routine cleaning intervals mandated by Urban Utilities (ranging from 4 to 12 weeks)",TRUE,"")} -> Mandatory compliance with Unitywater Trade Waste Policy & scheduled pump-outs | G6: {=_xlfn.IFS(TRIM(B6)="Sunshine Coast", "Unitywater Trade Waste Permit / MS Loop Food Folder", TRIM(B6)="Moreton Bay", "Water Supply (Safety and Reliability) Act 2008 / Unitywater Policy", TRIM(B6)="Gold Coast", "City of Gold Coast Liquid Trade Waste Guidelines", TRIM(B6)="Ipswich", "Urban Utilities Trade Waste Program / Ipswich Environmental Health Regs", TRUE, "")} -> Water Supply (Safety and Reliability) Act 2008 / Unitywater Policy
A7: Coomera | B7: Gold Coast | C7: {=_xlfn.IFS(TRIM(B7)="Sunshine Coast","Sunshine Coast Council",TRIM(B7)="Moreton Bay","City of Moreton Bay",TRIM(B7)="Gold Coast","City of Gold Coast",TRIM(B7)="Ipswich","Ipswich City Council",TRUE,"")} -> City of Gold Coast | D7: {=_xlfn.IFS(TRIM(B7)="Sunshine Coast","Biosecurity & Trade Waste Liquid Risk",TRIM(B7)="Moreton Bay","Commercial Effluent & Sewer Network Blockage Risk",TRIM(B7)="Gold Coast","FOG (Fats, Oils & Grease) Overload Risk",TRIM(B7)="Ipswich","Liquid Trade Waste Compliance & Pathogen Risk",TRUE,"")} -> FOG (Fats, Oils & Grease) Overload Risk | E7: {=_xlfn.IFS(TRIM(B7)="Sunshine Coast","Grease Trap Maintenance Log & Food Safety Supervisor Certificate Validation",TRIM(B7)="Moreton Bay","Unitywater Digital QR Code Tag Scan & Settleable Solids Log",TRIM(B7)="Gold Coast","Licensed Liquid Waste Contractor Extraction & Baffle Structural Check",TRIM(B7)="Ipswich","Urban Utilities Approved Sizing Metric & 25% FOG Accumulation Audit",TRUE,"")} -> Licensed Liquid Waste Contractor Extraction & Baffle Structural Check | F7: {=_xlfn.IFS(TRIM(B7)="Sunshine Coast","A mandatory grease arrestor pump-out every 13 weeks minimum",TRIM(B7)="Moreton Bay","Mandatory compliance with Unitywater Trade Waste Policy & scheduled pump-outs",TRIM(B7)="Gold Coast","All wastewater from food prep, floor wastes, and dishwashers must pass through approved trap",TRIM(B7)="Ipswich","Routine cleaning intervals mandated by Urban Utilities (ranging from 4 to 12 weeks)",TRUE,"")} -> All wastewater from food prep, floor wastes, and dishwashers must pass through approved trap | G7: {=_xlfn.IFS(TRIM(B7)="Sunshine Coast", "Unitywater Trade Waste Permit / MS Loop Food Folder", TRIM(B7)="Moreton Bay", "Water Supply (Safety and Reliability) Act 2008 / Unitywater Policy", TRIM(B7)="Gold Coast", "City of Gold Coast Liquid Trade Waste Guidelines", TRIM(B7)="Ipswich", "Urban Utilities Trade Waste Program / Ipswich Environmental Health Regs", TRUE, "")} -> City of Gold Coast Liquid Trade Waste Guidelines
A8: Dakabin | B8: Moreton Bay | C8: {=_xlfn.IFS(TRIM(B8)="Sunshine Coast","Sunshine Coast Council",TRIM(B8)="Moreton Bay","City of Moreton Bay",TRIM(B8)="Gold Coast","City of Gold Coast",TRIM(B8)="Ipswich","Ipswich City Council",TRUE,"")} -> City of Moreton Bay | D8: {=_xlfn.IFS(TRIM(B8)="Sunshine Coast","Biosecurity & Trade Waste Liquid Risk",TRIM(B8)="Moreton Bay","Commercial Effluent & Sewer Network Blockage Risk",TRIM(B8)="Gold Coast","FOG (Fats, Oils & Grease) Overload Risk",TRIM(B8)="Ipswich","Liquid Trade Waste Compliance & Pathogen Risk",TRUE,"")} -> Commercial Effluent & Sewer Network Blockage Risk | E8: {=_xlfn.IFS(TRIM(B8)="Sunshine Coast","Grease Trap Maintenance Log & Food Safety Supervisor Certificate Validation",TRIM(B8)="Moreton Bay","Unitywater Digital QR Code Tag Scan & Settleable Solids Log",TRIM(B8)="Gold Coast","Licensed Liquid Waste Contractor Extraction & Baffle Structural Check",TRIM(B8)="Ipswich","Urban Utilities Approved Sizing Metric & 25% FOG Accumulation Audit",TRUE,"")} -> Unitywater Digital QR Code Tag Scan & Settleable Solids Log | F8: {=_xlfn.IFS(TRIM(B8)="Sunshine Coast","A mandatory grease arrestor pump-out every 13 weeks minimum",TRIM(B8)="Moreton Bay","Mandatory compliance with Unitywater Trade Waste Policy & scheduled pump-outs",TRIM(B8)="Gold Coast","All wastewater from food prep, floor wastes, and dishwashers must pass through approved trap",TRIM(B8)="Ipswich","Routine cleaning intervals mandated by Urban Utilities (ranging from 4 to 12 weeks)",TRUE,"")} -> Mandatory compliance with Unitywater Trade Waste Policy & scheduled pump-outs | G8: {=_xlfn.IFS(TRIM(B8)="Sunshine Coast", "Unitywater Trade Waste Permit / MS Loop Food Folder", TRIM(B8)="Moreton Bay", "Water Supply (Safety and Reliability) Act 2008 / Unitywater Policy", TRIM(B8)="Gold Coast", "City of Gold Coast Liquid Trade Waste Guidelines", TRIM(B8)="Ipswich", "Urban Utilities Trade Waste Program / Ipswich Environmental Health Regs", TRUE, "")} -> Water Supply (Safety and Reliability) Act 2008 / Unitywater Policy
A9: Elimbah | B9: Sunshine Coast | C9: {=_xlfn.IFS(TRIM(B9)="Sunshine Coast","Sunshine Coast Council",TRIM(B9)="Moreton Bay","City of Moreton Bay",TRIM(B9)="Gold Coast","City of Gold Coast",TRIM(B9)="Ipswich","Ipswich City Council",TRUE,"")} -> Sunshine Coast Council | D9: {=_xlfn.IFS(TRIM(B9)="Sunshine Coast","Biosecurity & Trade Waste Liquid Risk",TRIM(B9)="Moreton Bay","Commercial Effluent & Sewer Network Blockage Risk",TRIM(B9)="Gold Coast","FOG (Fats, Oils & Grease) Overload Risk",TRIM(B9)="Ipswich","Liquid Trade Waste Compliance & Pathogen Risk",TRUE,"")} -> Biosecurity & Trade Waste Liquid Risk | E9: {=_xlfn.IFS(TRIM(B9)="Sunshine Coast","Grease Trap Maintenance Log & Food Safety Supervisor Certificate Validation",TRIM(B9)="Moreton Bay","Unitywater Digital QR Code Tag Scan & Settleable Solids Log",TRIM(B9)="Gold Coast","Licensed Liquid Waste Contractor Extraction & Baffle Structural Check",TRIM(B9)="Ipswich","Urban Utilities Approved Sizing Metric & 25% FOG Accumulation Audit",TRUE,"")} -> Grease Trap Maintenance Log & Food Safety Supervisor Certificate Validation | F9: {=_xlfn.IFS(TRIM(B9)="Sunshine Coast","A mandatory grease arrestor pump-out every 13 weeks minimum",TRIM(B9)="Moreton Bay","Mandatory compliance with Unitywater Trade Waste Policy & scheduled pump-outs",TRIM(B9)="Gold Coast","All wastewater from food prep, floor wastes, and dishwashers must pass through approved trap",TRIM(B9)="Ipswich","Routine cleaning intervals mandated by Urban Utilities (ranging from 4 to 12 weeks)",TRUE,"")} -> A mandatory grease arrestor pump-out every 13 weeks minimum | G9: {=_xlfn.IFS(TRIM(B9)="Sunshine Coast", "Unitywater Trade Waste Permit / MS Loop Food Folder", TRIM(B9)="Moreton Bay", "Water Supply (Safety and Reliability) Act 2008 / Unitywater Policy", TRIM(B9)="Gold Coast", "City of Gold Coast Liquid Trade Waste Guidelines", TRIM(B9)="Ipswich", "Urban Utilities Trade Waste Program / Ipswich Environmental Health Regs", TRUE, "")} -> Unitywater Trade Waste Permit / MS Loop Food Folder
A10: Eudlo | B10: Sunshine Coast | C10: {=_xlfn.IFS(TRIM(B10)="Sunshine Coast","Sunshine Coast Council",TRIM(B10)="Moreton Bay","City of Moreton Bay",TRIM(B10)="Gold Coast","City of Gold Coast",TRIM(B10)="Ipswich","Ipswich City Council",TRUE,"")} -> Sunshine Coast Council | D10: {=_xlfn.IFS(TRIM(B10)="Sunshine Coast","Biosecurity & Trade Waste Liquid Risk",TRIM(B10)="Moreton Bay","Commercial Effluent & Sewer Network Blockage Risk",TRIM(B10)="Gold Coast","FOG (Fats, Oils & Grease) Overload Risk",TRIM(B10)="Ipswich","Liquid Trade Waste Compliance & Pathogen Risk",TRUE,"")} -> Biosecurity & Trade Waste Liquid Risk | E10: {=_xlfn.IFS(TRIM(B10)="Sunshine Coast","Grease Trap Maintenance Log & Food Safety Supervisor Certificate Validation",TRIM(B10)="Moreton Bay","Unitywater Digital QR Code Tag Scan & Settleable Solids Log",TRIM(B10)="Gold Coast","Licensed Liquid Waste Contractor Extraction & Baffle Structural Check",TRIM(B10)="Ipswich","Urban Utilities Approved Sizing Metric & 25% FOG Accumulation Audit",TRUE,"")} -> Grease Trap Maintenance Log & Food Safety Supervisor Certificate Validation | F10: {=_xlfn.IFS(TRIM(B10)="Sunshine Coast","A mandatory grease arrestor pump-out every 13 weeks minimum",TRIM(B10)="Moreton Bay","Mandatory compliance with Unitywater Trade Waste Policy & scheduled pump-outs",TRIM(B10)="Gold Coast","All wastewater from food prep, floor wastes, and dishwashers must pass through approved trap",TRIM(B10)="Ipswich","Routine cleaning intervals mandated by Urban Utilities (ranging from 4 to 12 weeks)",TRUE,"")} -> A mandatory grease arrestor pump-out every 13 weeks minimum | G10: {=_xlfn.IFS(TRIM(B10)="Sunshine Coast", "Unitywater Trade Waste Permit / MS Loop Food Folder", TRIM(B10)="Moreton Bay", "Water Supply (Safety and Reliability) Act 2008 / Unitywater Policy", TRIM(B10)="Gold Coast", "City of Gold Coast Liquid Trade Waste Guidelines", TRIM(B10)="Ipswich", "Urban Utilities Trade Waste Program / Ipswich Environmental Health Regs", TRUE, "")} -> Unitywater Trade Waste Permit / MS Loop Food Folder
A11: Glass House Mountains | B11: Sunshine Coast | C11: {=_xlfn.IFS(TRIM(B11)="Sunshine Coast","Sunshine Coast Council",TRIM(B11)="Moreton Bay","City of Moreton Bay",TRIM(B11)="Gold Coast","City of Gold Coast",TRIM(B11)="Ipswich","Ipswich City Council",TRUE,"")} -> Sunshine Coast Council | D11: {=_xlfn.IFS(TRIM(B11)="Sunshine Coast","Biosecurity & Trade Waste Liquid Risk",TRIM(B11)="Moreton Bay","Commercial Effluent & Sewer Network Blockage Risk",TRIM(B11)="Gold Coast","FOG (Fats, Oils & Grease) Overload Risk",TRIM(B11)="Ipswich","Liquid Trade Waste Compliance & Pathogen Risk",TRUE,"")} -> Biosecurity & Trade Waste Liquid Risk | E11: {=_xlfn.IFS(TRIM(B11)="Sunshine Coast","Grease Trap Maintenance Log & Food Safety Supervisor Certificate Validation",TRIM(B11)="Moreton Bay","Unitywater Digital QR Code Tag Scan & Settleable Solids Log",TRIM(B11)="Gold Coast","Licensed Liquid Waste Contractor Extraction & Baffle Structural Check",TRIM(B11)="Ipswich","Urban Utilities Approved Sizing Metric & 25% FOG Accumulation Audit",TRUE,"")} -> Grease Trap Maintenance Log & Food Safety Supervisor Certificate Validation | F11: {=_xlfn.IFS(TRIM(B11)="Sunshine Coast","A mandatory grease arrestor pump-out every 13 weeks minimum",TRIM(B11)="Moreton Bay","Mandatory compliance with Unitywater Trade Waste Policy & scheduled pump-outs",TRIM(B11)="Gold Coast","All wastewater from food prep, floor wastes, and dishwashers must pass through approved trap",TRIM(B11)="Ipswich","Routine cleaning intervals mandated by Urban Utilities (ranging from 4 to 12 weeks)",TRUE,"")} -> A mandatory grease arrestor pump-out every 13 weeks minimum | G11: {=_xlfn.IFS(TRIM(B11)="Sunshine Coast", "Unitywater Trade Waste Permit / MS Loop Food Folder", TRIM(B11)="Moreton Bay", "Water Supply (Safety and Reliability) Act 2008 / Unitywater Policy", TRIM(B11)="Gold Coast", "City of Gold Coast Liquid Trade Waste Guidelines", TRIM(B11)="Ipswich", "Urban Utilities Trade Waste Program / Ipswich Environmental Health Regs", TRUE, "")} -> Unitywater Trade Waste Permit / MS Loop Food Folder
A12: Helensvale | B12: Gold Coast | C12: {=_xlfn.IFS(TRIM(B12)="Sunshine Coast","Sunshine Coast Council",TRIM(B12)="Moreton Bay","City of Moreton Bay",TRIM(B12)="Gold Coast","City of Gold Coast",TRIM(B12)="Ipswich","Ipswich City Council",TRUE,"")} -> City of Gold Coast | D12: {=_xlfn.IFS(TRIM(B12)="Sunshine Coast","Biosecurity & Trade Waste Liquid Risk",TRIM(B12)="Moreton Bay","Commercial Effluent & Sewer Network Blockage Risk",TRIM(B12)="Gold Coast","FOG (Fats, Oils & Grease) Overload Risk",TRIM(B12)="Ipswich","Liquid Trade Waste Compliance & Pathogen Risk",TRUE,"")} -> FOG (Fats, Oils & Grease) Overload Risk | E12: {=_xlfn.IFS(TRIM(B12)="Sunshine Coast","Grease Trap Maintenance Log & Food Safety Supervisor Certificate Validation",TRIM(B12)="Moreton Bay","Unitywater Digital QR Code Tag Scan & Settleable Solids Log",TRIM(B12)="Gold Coast","Licensed Liquid Waste Contractor Extraction & Baffle Structural Check",TRIM(B12)="Ipswich","Urban Utilities Approved Sizing Metric & 25% FOG Accumulation Audit",TRUE,"")} -> Licensed Liquid Waste Contractor Extraction & Baffle Structural Check | F12: {=_xlfn.IFS(TRIM(B12)="Sunshine Coast","A mandatory grease arrestor pump-out every 13 weeks minimum",TRIM(B12)="Moreton Bay","Mandatory compliance with Unitywater Trade Waste Policy & scheduled pump-outs",TRIM(B12)="Gold Coast","All wastewater from food prep, floor wastes, and dishwashers must pass through approved trap",TRIM(B12)="Ipswich","Routine cleaning intervals mandated by Urban Utilities (ranging from 4 to 12 weeks)",TRUE,"")} -> All wastewater from food prep, floor wastes, and dishwashers must pass through approved trap | G12: {=_xlfn.IFS(TRIM(B12)="Sunshine Coast", "Unitywater Trade Waste Permit / MS Loop Food Folder", TRIM(B12)="Moreton Bay", "Water Supply (Safety and Reliability) Act 2008 / Unitywater Policy", TRIM(B12)="Gold Coast", "City of Gold Coast Liquid Trade Waste Guidelines", TRIM(B12)="Ipswich", "Urban Utilities Trade Waste Program / Ipswich Environmental Health Regs", TRUE, "")} -> City of Gold Coast Liquid Trade Waste Guidelines
A13: Hope Island | B13: Gold Coast | C13: {=_xlfn.IFS(TRIM(B13)="Sunshine Coast","Sunshine Coast Council",TRIM(B13)="Moreton Bay","City of Moreton Bay",TRIM(B13)="Gold Coast","City of Gold Coast",TRIM(B13)="Ipswich","Ipswich City Council",TRUE,"")} -> City of Gold Coast | D13: {=_xlfn.IFS(TRIM(B13)="Sunshine Coast","Biosecurity & Trade Waste Liquid Risk",TRIM(B13)="Moreton Bay","Commercial Effluent & Sewer Network Blockage Risk",TRIM(B13)="Gold Coast","FOG (Fats, Oils & Grease) Overload Risk",TRIM(B13)="Ipswich","Liquid Trade Waste Compliance & Pathogen Risk",TRUE,"")} -> FOG (Fats, Oils & Grease) Overload Risk | E13: {=_xlfn.IFS(TRIM(B13)="Sunshine Coast","Grease Trap Maintenance Log & Food Safety Supervisor Certificate Validation",TRIM(B13)="Moreton Bay","Unitywater Digital QR Code Tag Scan & Settleable Solids Log",TRIM(B13)="Gold Coast","Licensed Liquid Waste Contractor Extraction & Baffle Structural Check",TRIM(B13)="Ipswich","Urban Utilities Approved Sizing Metric & 25% FOG Accumulation Audit",TRUE,"")} -> Licensed Liquid Waste Contractor Extraction & Baffle Structural Check | F13: {=_xlfn.IFS(TRIM(B13)="Sunshine Coast","A mandatory grease arrestor pump-out every 13 weeks minimum",TRIM(B13)="Moreton Bay","Mandatory compliance with Unitywater Trade Waste Policy & scheduled pump-outs",TRIM(B13)="Gold Coast","All wastewater from food prep, floor wastes, and dishwashers must pass through approved trap",TRIM(B13)="Ipswich","Routine cleaning intervals mandated by Urban Utilities (ranging from 4 to 12 weeks)",TRUE,"")} -> All wastewater from food prep, floor wastes, and dishwashers must pass through approved trap | G13: {=_xlfn.IFS(TRIM(B13)="Sunshine Coast", "Unitywater Trade Waste Permit / MS Loop Food Folder", TRIM(B13)="Moreton Bay", "Water Supply (Safety and Reliability) Act 2008 / Unitywater Policy", TRIM(B13)="Gold Coast", "City of Gold Coast Liquid Trade Waste Guidelines", TRIM(B13)="Ipswich", "Urban Utilities Trade Waste Program / Ipswich Environmental Health Regs", TRUE, "")} -> City of Gold Coast Liquid Trade Waste Guidelines
A14: Ipswich CBD | B14: Ipswich | C14: {=_xlfn.IFS(TRIM(B14)="Sunshine Coast","Sunshine Coast Council",TRIM(B14)="Moreton Bay","City of Moreton Bay",TRIM(B14)="Gold Coast","City of Gold Coast",TRIM(B14)="Ipswich","Ipswich City Council",TRUE,"")} -> Ipswich City Council | D14: {=_xlfn.IFS(TRIM(B14)="Sunshine Coast","Biosecurity & Trade Waste Liquid Risk",TRIM(B14)="Moreton Bay","Commercial Effluent & Sewer Network Blockage Risk",TRIM(B14)="Gold Coast","FOG (Fats, Oils & Grease) Overload Risk",TRIM(B14)="Ipswich","Liquid Trade Waste Compliance & Pathogen Risk",TRUE,"")} -> Liquid Trade Waste Compliance & Pathogen Risk | E14: {=_xlfn.IFS(TRIM(B14)="Sunshine Coast","Grease Trap Maintenance Log & Food Safety Supervisor Certificate Validation",TRIM(B14)="Moreton Bay","Unitywater Digital QR Code Tag Scan & Settleable Solids Log",TRIM(B14)="Gold Coast","Licensed Liquid Waste Contractor Extraction & Baffle Structural Check",TRIM(B14)="Ipswich","Urban Utilities Approved Sizing Metric & 25% FOG Accumulation Audit",TRUE,"")} -> Urban Utilities Approved Sizing Metric & 25% FOG Accumulation Audit | F14: {=_xlfn.IFS(TRIM(B14)="Sunshine Coast","A mandatory grease arrestor pump-out every 13 weeks minimum",TRIM(B14)="Moreton Bay","Mandatory compliance with Unitywater Trade Waste Policy & scheduled pump-outs",TRIM(B14)="Gold Coast","All wastewater from food prep, floor wastes, and dishwashers must pass through approved trap",TRIM(B14)="Ipswich","Routine cleaning intervals mandated by Urban Utilities (ranging from 4 to 12 weeks)",TRUE,"")} -> Routine cleaning intervals mandated by Urban Utilities (ranging from 4 to 12 weeks) | G14: {=_xlfn.IFS(TRIM(B14)="Sunshine Coast", "Unitywater Trade Waste Permit / MS Loop Food Folder", TRIM(B14)="Moreton Bay", "Water Supply (Safety and Reliability) Act 2008 / Unitywater Policy", TRIM(B14)="Gold Coast", "City of Gold Coast Liquid Trade Waste Guidelines", TRIM(B14)="Ipswich", "Urban Utilities Trade Waste Program / Ipswich Environmental Health Regs", TRUE, "")} -> Urban Utilities Trade Waste Program / Ipswich Environmental Health Regs
... A38: Woombye | B38: Sunshine Coast | C38: {=_xlfn.IFS(TRIM(B38)="Sunshine Coast","Sunshine Coast Council",TRIM(B38)="Moreton Bay","City of Moreton Bay",TRIM(B38)="Gold Coast","City of Gold Coast",TRIM(B38)="Ipswich","Ipswich City Council",TRUE,"")} -> Sunshine Coast Council | D38: {=_xlfn.IFS(TRIM(B38)="Sunshine Coast","Biosecurity & Trade Waste Liquid Risk",TRIM(B38)="Moreton Bay","Commercial Effluent & Sewer Network Blockage Risk",TRIM(B38)="Gold Coast","FOG (Fats, Oils & Grease) Overload Risk",TRIM(B38)="Ipswich","Liquid Trade Waste Compliance & Pathogen Risk",TRUE,"")} -> Biosecurity & Trade Waste Liquid Risk | E38: {=_xlfn.IFS(TRIM(B38)="Sunshine Coast","Grease Trap Maintenance Log & Food Safety Supervisor Certificate Validation",TRIM(B38)="Moreton Bay","Unitywater Digital QR Code Tag Scan & Settleable Solids Log",TRIM(B38)="Gold Coast","Licensed Liquid Waste Contractor Extraction & Baffle Structural Check",TRIM(B38)="Ipswich","Urban Utilities Approved Sizing Metric & 25% FOG Accumulation Audit",TRUE,"")} -> Grease Trap Maintenance Log & Food Safety Supervisor Certificate Validation | F38: {=_xlfn.IFS(TRIM(B38)="Sunshine Coast","A mandatory grease arrestor pump-out every 13 weeks minimum",TRIM(B38)="Moreton Bay","Mandatory compliance with Unitywater Trade Waste Policy & scheduled pump-outs",TRIM(B38)="Gold Coast","All wastewater from food prep, floor wastes, and dishwashers must pass through approved trap",TRIM(B38)="Ipswich","Routine cleaning intervals mandated by Urban Utilities (ranging from 4 to 12 weeks)",TRUE,"")} -> A mandatory grease arrestor pump-out every 13 weeks minimum | G38: {=_xlfn.IFS(TRIM(B38)="Sunshine Coast", "Unitywater Trade Waste Permit / MS Loop Food Folder", TRIM(B38)="Moreton Bay", "Water Supply (Safety and Reliability) Act 2008 / Unitywater Policy", TRIM(B38)="Gold Coast", "City of Gold Coast Liquid Trade Waste Guidelines", TRIM(B38)="Ipswich", "Urban Utilities Trade Waste Program / Ipswich Environmental Health Regs", TRUE, "")} -> Unitywater Trade Waste Permit / MS Loop Food Folder

Sheet Furniture
A1: Furniture Data from Gold Coast to Sunshine Coast | H1: Date | I1: 26.06.2026
A2: Suburb / Node | B2: Geographic Zone | C2: Governance Authority | D2: Key Risk Category | E2: Compliance Checklist / Metric | F2: Requirements | G2: Data Source / Link
A3: Beerburrum | B3: Sunshine Coast | C3: {=_xlfn.IFS(TRIM(B3)="Sunshine Coast","Sunshine Coast Council",TRIM(B3)="Moreton Bay","City of Moreton Bay",TRIM(B3)="Gold Coast","City of Gold Coast",TRIM(B3)="Ipswich","Ipswich City Council",TRUE,"")} -> Sunshine Coast Council | D3: {=_xlfn.IFS(TRIM(B3)="Sunshine Coast", "Combustible Dust Control & Air Quality Risk", TRIM(B3)="Moreton Bay", "Surface Coating & Hazardous Chemical Vapor Risk", TRIM(B3)="Gold Coast", "Industrial Noise & Fine Particulate Matter Risk", TRIM(B3)="Ipswich", "Solid Timber Waste & Stockpile Fire Risk", TRUE, "")} -> Combustible Dust Control & Air Quality Risk | E3: {=_xlfn.IFS(TRIM(B3)="Sunshine Coast", "LEV (Local Exhaust Ventilation) Particle Testing & Pressure Drop Log", TRIM(B3)="Moreton Bay", "Spray Booth Airflow Velocity Log & VOC Emission Check", TRIM(B3)="Gold Coast", "Boundary Acoustic dB Measurement & Baghouse Filter Differential Pressure Audit", TRIM(B3)="Ipswich", "Timber Waste Skip Clearance Frequency & Dust Extraction Silo Spark Detection Log", TRUE, "")} -> LEV (Local Exhaust Ventilation) Particle Testing & Pressure Drop Log | F3: {=_xlfn.IFS(TRIM(B3)="Sunshine Coast", "Maintain dust extraction air velocity above 20 m/s at all extraction hoods", TRIM(B3)="Moreton Bay", "Comply with AS/NZS 4114 for spray painting booths and maintain active charcoal filters", TRIM(B3)="Gold Coast", "Enclose high-noise machinery (CNC routers, planers) and monitor exhaust filter integrity daily", TRIM(B3)="Ipswich", "Clear sawdust silos before reaching 80% capacity and separate treated vs. untreated timber scraps", TRUE, "")} -> Maintain dust extraction air velocity above 20 m/s at all extraction hoods | G3: {=_xlfn.IFS(TRIM(B3)="Sunshine Coast", "WorkSafe QLD Woodworking Code / MS Loop Furniture Folder", TRIM(B3)="Moreton Bay", "Environmental Protection Regulation 2019 (Surface Coating)", TRIM(B3)="Gold Coast", "City of Gold Coast Noise Management Guidelines", TRIM(B3)="Ipswich", "Ipswich City Council Waste Management Bylaws / Loop Master Register", TRUE, "")} -> WorkSafe QLD Woodworking Code / MS Loop Furniture Folder
A4: Beerwah | B4: Sunshine Coast | C4: {=_xlfn.IFS(TRIM(B4)="Sunshine Coast","Sunshine Coast Council",TRIM(B4)="Moreton Bay","City of Moreton Bay",TRIM(B4)="Gold Coast","City of Gold Coast",TRIM(B4)="Ipswich","Ipswich City Council",TRUE,"")} -> Sunshine Coast Council | D4: {=_xlfn.IFS(TRIM(B4)="Sunshine Coast", "Combustible Dust Control & Air Quality Risk", TRIM(B4)="Moreton Bay", "Surface Coating & Hazardous Chemical Vapor Risk", TRIM(B4)="Gold Coast", "Industrial Noise & Fine Particulate Matter Risk", TRIM(B4)="Ipswich", "Solid Timber Waste & Stockpile Fire Risk", TRUE, "")} -> Combustible Dust Control & Air Quality Risk | E4: {=_xlfn.IFS(TRIM(B4)="Sunshine Coast", "LEV (Local Exhaust Ventilation) Particle Testing & Pressure Drop Log", TRIM(B4)="Moreton Bay", "Spray Booth Airflow Velocity Log & VOC Emission Check", TRIM(B4)="Gold Coast", "Boundary Acoustic dB Measurement & Baghouse Filter Differential Pressure Audit", TRIM(B4)="Ipswich", "Timber Waste Skip Clearance Frequency & Dust Extraction Silo Spark Detection Log", TRUE, "")} -> LEV (Local Exhaust Ventilation) Particle Testing & Pressure Drop Log | F4: {=_xlfn.IFS(TRIM(B4)="Sunshine Coast", "Maintain dust extraction air velocity above 20 m/s at all extraction hoods", TRIM(B4)="Moreton Bay", "Comply with AS/NZS 4114 for spray painting booths and maintain active charcoal filters", TRIM(B4)="Gold Coast", "Enclose high-noise machinery (CNC routers, planers) and monitor exhaust filter integrity daily", TRIM(B4)="Ipswich", "Clear sawdust silos before reaching 80% capacity and separate treated vs. untreated timber scraps", TRUE, "")} -> Maintain dust extraction air velocity above 20 m/s at all extraction hoods | G4: {=_xlfn.IFS(TRIM(B4)="Sunshine Coast", "WorkSafe QLD Woodworking Code / MS Loop Furniture Folder", TRIM(B4)="Moreton Bay", "Environmental Protection Regulation 2019 (Surface Coating)", TRIM(B4)="Gold Coast", "City of Gold Coast Noise Management Guidelines", TRIM(B4)="Ipswich", "Ipswich City Council Waste Management Bylaws / Loop Master Register", TRUE, "")} -> WorkSafe QLD Woodworking Code / MS Loop Furniture Folder
A5: Burpengary | B5: Moreton Bay | C5: {=_xlfn.IFS(TRIM(B5)="Sunshine Coast","Sunshine Coast Council",TRIM(B5)="Moreton Bay","City of Moreton Bay",TRIM(B5)="Gold Coast","City of Gold Coast",TRIM(B5)="Ipswich","Ipswich City Council",TRUE,"")} -> City of Moreton Bay | D5: {=_xlfn.IFS(TRIM(B5)="Sunshine Coast", "Combustible Dust Control & Air Quality Risk", TRIM(B5)="Moreton Bay", "Surface Coating & Hazardous Chemical Vapor Risk", TRIM(B5)="Gold Coast", "Industrial Noise & Fine Particulate Matter Risk", TRIM(B5)="Ipswich", "Solid Timber Waste & Stockpile Fire Risk", TRUE, "")} -> Surface Coating & Hazardous Chemical Vapor Risk | E5: {=_xlfn.IFS(TRIM(B5)="Sunshine Coast", "LEV (Local Exhaust Ventilation) Particle Testing & Pressure Drop Log", TRIM(B5)="Moreton Bay", "Spray Booth Airflow Velocity Log & VOC Emission Check", TRIM(B5)="Gold Coast", "Boundary Acoustic dB Measurement & Baghouse Filter Differential Pressure Audit", TRIM(B5)="Ipswich", "Timber Waste Skip Clearance Frequency & Dust Extraction Silo Spark Detection Log", TRUE, "")} -> Spray Booth Airflow Velocity Log & VOC Emission Check | F5: {=_xlfn.IFS(TRIM(B5)="Sunshine Coast", "Maintain dust extraction air velocity above 20 m/s at all extraction hoods", TRIM(B5)="Moreton Bay", "Comply with AS/NZS 4114 for spray painting booths and maintain active charcoal filters", TRIM(B5)="Gold Coast", "Enclose high-noise machinery (CNC routers, planers) and monitor exhaust filter integrity daily", TRIM(B5)="Ipswich", "Clear sawdust silos before reaching 80% capacity and separate treated vs. untreated timber scraps", TRUE, "")} -> Comply with AS/NZS 4114 for spray painting booths and maintain active charcoal filters | G5: {=_xlfn.IFS(TRIM(B5)="Sunshine Coast", "WorkSafe QLD Woodworking Code / MS Loop Furniture Folder", TRIM(B5)="Moreton Bay", "Environmental Protection Regulation 2019 (Surface Coating)", TRIM(B5)="Gold Coast", "City of Gold Coast Noise Management Guidelines", TRIM(B5)="Ipswich", "Ipswich City Council Waste Management Bylaws / Loop Master Register", TRUE, "")} -> Environmental Protection Regulation 2019 (Surface Coating)
A6: Caboolture | B6: Moreton Bay | C6: {=_xlfn.IFS(TRIM(B6)="Sunshine Coast","Sunshine Coast Council",TRIM(B6)="Moreton Bay","City of Moreton Bay",TRIM(B6)="Gold Coast","City of Gold Coast",TRIM(B6)="Ipswich","Ipswich City Council",TRUE,"")} -> City of Moreton Bay | D6: {=_xlfn.IFS(TRIM(B6)="Sunshine Coast", "Combustible Dust Control & Air Quality Risk", TRIM(B6)="Moreton Bay", "Surface Coating & Hazardous Chemical Vapor Risk", TRIM(B6)="Gold Coast", "Industrial Noise & Fine Particulate Matter Risk", TRIM(B6)="Ipswich", "Solid Timber Waste & Stockpile Fire Risk", TRUE, "")} -> Surface Coating & Hazardous Chemical Vapor Risk | E6: {=_xlfn.IFS(TRIM(B6)="Sunshine Coast", "LEV (Local Exhaust Ventilation) Particle Testing & Pressure Drop Log", TRIM(B6)="Moreton Bay", "Spray Booth Airflow Velocity Log & VOC Emission Check", TRIM(B6)="Gold Coast", "Boundary Acoustic dB Measurement & Baghouse Filter Differential Pressure Audit", TRIM(B6)="Ipswich", "Timber Waste Skip Clearance Frequency & Dust Extraction Silo Spark Detection Log", TRUE, "")} -> Spray Booth Airflow Velocity Log & VOC Emission Check | F6: {=_xlfn.IFS(TRIM(B6)="Sunshine Coast", "Maintain dust extraction air velocity above 20 m/s at all extraction hoods", TRIM(B6)="Moreton Bay", "Comply with AS/NZS 4114 for spray painting booths and maintain active charcoal filters", TRIM(B6)="Gold Coast", "Enclose high-noise machinery (CNC routers, planers) and monitor exhaust filter integrity daily", TRIM(B6)="Ipswich", "Clear sawdust silos before reaching 80% capacity and separate treated vs. untreated timber scraps", TRUE, "")} -> Comply with AS/NZS 4114 for spray painting booths and maintain active charcoal filters | G6: {=_xlfn.IFS(TRIM(B6)="Sunshine Coast", "WorkSafe QLD Woodworking Code / MS Loop Furniture Folder", TRIM(B6)="Moreton Bay", "Environmental Protection Regulation 2019 (Surface Coating)", TRIM(B6)="Gold Coast", "City of Gold Coast Noise Management Guidelines", TRIM(B6)="Ipswich", "Ipswich City Council Waste Management Bylaws / Loop Master Register", TRUE, "")} -> Environmental Protection Regulation 2019 (Surface Coating)
